[18-May-25 13:18:54 - INFO] - Reex.core.mongo - Connecting to your Mongo Database...
[18-May-25 13:18:55 - INFO] - Reex.core.mongo - Connected to your Mongo Database.
[18-May-25 13:18:55 - INFO] - Reex.core.dir - Directories Updated.
[18-May-25 13:18:55 - INFO] - Reex.core.git - Git Client Found [VPS DEPLOYER]
[18-May-25 13:18:55 - INFO] - Reex.misc - Local Database Initialized.
[18-May-25 13:18:55 - INFO] - Reex.core.bot - Starting Bot...
[18-May-25 13:19:00 - INFO] - Reex.misc - Sudoers Loaded.
[18-May-25 13:30:51 - INFO] - Reex.core.mongo - Connecting to your Mongo Database...
[18-May-25 13:30:52 - INFO] - Reex.core.mongo - Connected to your Mongo Database.
[18-May-25 13:30:52 - INFO] - Reex.core.dir - Directories Updated.
[18-May-25 13:30:52 - INFO] - Reex.core.git - Git Client Found [VPS DEPLOYER]
[18-May-25 13:30:52 - INFO] - Reex.misc - Local Database Initialized.
[18-May-25 13:30:52 - INFO] - Reex.core.bot - Starting Bot...
[18-May-25 13:30:56 - INFO] - Reex.misc - Sudoers Loaded.
[18-May-25 13:31:04 - INFO] - AryaaMusic.plugins - Successfully Imported Modules...
[18-May-25 13:31:04 - INFO] - Reex.core.userbot - Starting Assistants...
[18-May-25 13:31:05 - INFO] - Reex.core.userbot - Assistant Started as <a href=tg://user?id=7068357086>a.</a>
[18-May-25 13:31:05 - INFO] - Reex.core.call - Starting PyTgCalls Client...

[18-May-25 13:31:17 - INFO] - AryaaMusic - AnonX Music Bot Started Successfully.

Don't forget to visit @FallenAssociation
[18-May-25 13:33:46 - ERROR] - asyncio - Task exception was never retrieved
future: <Task finished name='Task-1055' coro=<Client.handle_updates() done, defined at C:\Users\aryas\AppData\Local\Programs\Python\Python310\lib\site-packages\pyrogram\client.py:642> exception=AuthKeyDuplicated('Telegram says: [406 AUTH_KEY_DUPLICATED] (caused by "updates.GetChannelDifference") Pyrogram 2.3.62 thinks: The same authorization key (session file) was used in more than one place simultaneously. You must delete your session file and log in again with your phone number or bot token')>
Traceback (most recent call last):
  File "C:\Users\aryas\AppData\Local\Programs\Python\Python310\lib\site-packages\pyrogram\client.py", line 685, in handle_updates
    diff = await self.invoke(
  File "C:\Users\aryas\AppData\Local\Programs\Python\Python310\lib\site-packages\pyrogram\methods\advanced\invoke.py", line 80, in invoke
    r = await self.session.invoke(
  File "C:\Users\aryas\AppData\Local\Programs\Python\Python310\lib\site-packages\pyrogram\session\session.py", line 433, in invoke
    return await self.send(query, timeout=timeout)
  File "C:\Users\aryas\AppData\Local\Programs\Python\Python310\lib\site-packages\pyrogram\session\session.py", line 377, in send
    RPCError.raise_it(result, type(data))
  File "C:\Users\aryas\AppData\Local\Programs\Python\Python310\lib\site-packages\pyrogram\errors\rpc_error.py", line 93, in raise_it
    raise getattr(
pyrogram.errors.exceptions.not_acceptable_406.AuthKeyDuplicated: Telegram says: [406 AUTH_KEY_DUPLICATED] (caused by "updates.GetChannelDifference") Pyrogram 2.3.62 thinks: The same authorization key (session file) was used in more than one place simultaneously. You must delete your session file and log in again with your phone number or bot token
[18-May-25 13:33:46 - ERROR] - asyncio - Task exception was never retrieved
future: <Task finished name='Task-1056' coro=<Client.handle_updates() done, defined at C:\Users\aryas\AppData\Local\Programs\Python\Python310\lib\site-packages\pyrogram\client.py:642> exception=AuthKeyDuplicated('Telegram says: [406 AUTH_KEY_DUPLICATED] (caused by "updates.GetChannelDifference") Pyrogram 2.3.62 thinks: The same authorization key (session file) was used in more than one place simultaneously. You must delete your session file and log in again with your phone number or bot token')>
Traceback (most recent call last):
  File "C:\Users\aryas\AppData\Local\Programs\Python\Python310\lib\site-packages\pyrogram\client.py", line 685, in handle_updates
    diff = await self.invoke(
  File "C:\Users\aryas\AppData\Local\Programs\Python\Python310\lib\site-packages\pyrogram\methods\advanced\invoke.py", line 80, in invoke
    r = await self.session.invoke(
  File "C:\Users\aryas\AppData\Local\Programs\Python\Python310\lib\site-packages\pyrogram\session\session.py", line 433, in invoke
    return await self.send(query, timeout=timeout)
  File "C:\Users\aryas\AppData\Local\Programs\Python\Python310\lib\site-packages\pyrogram\session\session.py", line 377, in send
    RPCError.raise_it(result, type(data))
  File "C:\Users\aryas\AppData\Local\Programs\Python\Python310\lib\site-packages\pyrogram\errors\rpc_error.py", line 93, in raise_it
    raise getattr(
pyrogram.errors.exceptions.not_acceptable_406.AuthKeyDuplicated: Telegram says: [406 AUTH_KEY_DUPLICATED] (caused by "updates.GetChannelDifference") Pyrogram 2.3.62 thinks: The same authorization key (session file) was used in more than one place simultaneously. You must delete your session file and log in again with your phone number or bot token
[18-May-25 13:33:46 - ERROR] - asyncio - Task exception was never retrieved
future: <Task finished name='Task-1059' coro=<Client.handle_updates() done, defined at C:\Users\aryas\AppData\Local\Programs\Python\Python310\lib\site-packages\pyrogram\client.py:642> exception=AuthKeyDuplicated('Telegram says: [406 AUTH_KEY_DUPLICATED] (caused by "updates.GetChannelDifference") Pyrogram 2.3.62 thinks: The same authorization key (session file) was used in more than one place simultaneously. You must delete your session file and log in again with your phone number or bot token')>
Traceback (most recent call last):
  File "C:\Users\aryas\AppData\Local\Programs\Python\Python310\lib\site-packages\pyrogram\client.py", line 685, in handle_updates
    diff = await self.invoke(
  File "C:\Users\aryas\AppData\Local\Programs\Python\Python310\lib\site-packages\pyrogram\methods\advanced\invoke.py", line 80, in invoke
    r = await self.session.invoke(
  File "C:\Users\aryas\AppData\Local\Programs\Python\Python310\lib\site-packages\pyrogram\session\session.py", line 433, in invoke
    return await self.send(query, timeout=timeout)
  File "C:\Users\aryas\AppData\Local\Programs\Python\Python310\lib\site-packages\pyrogram\session\session.py", line 377, in send
    RPCError.raise_it(result, type(data))
  File "C:\Users\aryas\AppData\Local\Programs\Python\Python310\lib\site-packages\pyrogram\errors\rpc_error.py", line 93, in raise_it
    raise getattr(
pyrogram.errors.exceptions.not_acceptable_406.AuthKeyDuplicated: Telegram says: [406 AUTH_KEY_DUPLICATED] (caused by "updates.GetChannelDifference") Pyrogram 2.3.62 thinks: The same authorization key (session file) was used in more than one place simultaneously. You must delete your session file and log in again with your phone number or bot token
[18-May-25 13:33:51 - ERROR] - asyncio - Task exception was never retrieved
future: <Task finished name='Task-1098' coro=<Client.handle_updates() done, defined at C:\Users\aryas\AppData\Local\Programs\Python\Python310\lib\site-packages\pyrogram\client.py:642> exception=AuthKeyDuplicated('Telegram says: [406 AUTH_KEY_DUPLICATED] (caused by "updates.GetChannelDifference") Pyrogram 2.3.62 thinks: The same authorization key (session file) was used in more than one place simultaneously. You must delete your session file and log in again with your phone number or bot token')>
Traceback (most recent call last):
  File "C:\Users\aryas\AppData\Local\Programs\Python\Python310\lib\site-packages\pyrogram\client.py", line 685, in handle_updates
    diff = await self.invoke(
  File "C:\Users\aryas\AppData\Local\Programs\Python\Python310\lib\site-packages\pyrogram\methods\advanced\invoke.py", line 80, in invoke
    r = await self.session.invoke(
  File "C:\Users\aryas\AppData\Local\Programs\Python\Python310\lib\site-packages\pyrogram\session\session.py", line 433, in invoke
    return await self.send(query, timeout=timeout)
  File "C:\Users\aryas\AppData\Local\Programs\Python\Python310\lib\site-packages\pyrogram\session\session.py", line 377, in send
    RPCError.raise_it(result, type(data))
  File "C:\Users\aryas\AppData\Local\Programs\Python\Python310\lib\site-packages\pyrogram\errors\rpc_error.py", line 93, in raise_it
    raise getattr(
pyrogram.errors.exceptions.not_acceptable_406.AuthKeyDuplicated: Telegram says: [406 AUTH_KEY_DUPLICATED] (caused by "updates.GetChannelDifference") Pyrogram 2.3.62 thinks: The same authorization key (session file) was used in more than one place simultaneously. You must delete your session file and log in again with your phone number or bot token
[18-May-25 13:33:51 - ERROR] - asyncio - Task exception was never retrieved
future: <Task finished name='Task-1100' coro=<Client.handle_updates() done, defined at C:\Users\aryas\AppData\Local\Programs\Python\Python310\lib\site-packages\pyrogram\client.py:642> exception=AuthKeyDuplicated('Telegram says: [406 AUTH_KEY_DUPLICATED] (caused by "updates.GetChannelDifference") Pyrogram 2.3.62 thinks: The same authorization key (session file) was used in more than one place simultaneously. You must delete your session file and log in again with your phone number or bot token')>
Traceback (most recent call last):
  File "C:\Users\aryas\AppData\Local\Programs\Python\Python310\lib\site-packages\pyrogram\client.py", line 685, in handle_updates
    diff = await self.invoke(
  File "C:\Users\aryas\AppData\Local\Programs\Python\Python310\lib\site-packages\pyrogram\methods\advanced\invoke.py", line 80, in invoke
    r = await self.session.invoke(
  File "C:\Users\aryas\AppData\Local\Programs\Python\Python310\lib\site-packages\pyrogram\session\session.py", line 433, in invoke
    return await self.send(query, timeout=timeout)
  File "C:\Users\aryas\AppData\Local\Programs\Python\Python310\lib\site-packages\pyrogram\session\session.py", line 377, in send
    RPCError.raise_it(result, type(data))
  File "C:\Users\aryas\AppData\Local\Programs\Python\Python310\lib\site-packages\pyrogram\errors\rpc_error.py", line 93, in raise_it
    raise getattr(
pyrogram.errors.exceptions.not_acceptable_406.AuthKeyDuplicated: Telegram says: [406 AUTH_KEY_DUPLICATED] (caused by "updates.GetChannelDifference") Pyrogram 2.3.62 thinks: The same authorization key (session file) was used in more than one place simultaneously. You must delete your session file and log in again with your phone number or bot token
[18-May-25 13:33:56 - ERROR] - asyncio - Task exception was never retrieved
future: <Task finished name='Task-1130' coro=<Client.handle_updates() done, defined at C:\Users\aryas\AppData\Local\Programs\Python\Python310\lib\site-packages\pyrogram\client.py:642> exception=AuthKeyDuplicated('Telegram says: [406 AUTH_KEY_DUPLICATED] (caused by "updates.GetChannelDifference") Pyrogram 2.3.62 thinks: The same authorization key (session file) was used in more than one place simultaneously. You must delete your session file and log in again with your phone number or bot token')>
Traceback (most recent call last):
  File "C:\Users\aryas\AppData\Local\Programs\Python\Python310\lib\site-packages\pyrogram\client.py", line 685, in handle_updates
    diff = await self.invoke(
  File "C:\Users\aryas\AppData\Local\Programs\Python\Python310\lib\site-packages\pyrogram\methods\advanced\invoke.py", line 80, in invoke
    r = await self.session.invoke(
  File "C:\Users\aryas\AppData\Local\Programs\Python\Python310\lib\site-packages\pyrogram\session\session.py", line 433, in invoke
    return await self.send(query, timeout=timeout)
  File "C:\Users\aryas\AppData\Local\Programs\Python\Python310\lib\site-packages\pyrogram\session\session.py", line 377, in send
    RPCError.raise_it(result, type(data))
  File "C:\Users\aryas\AppData\Local\Programs\Python\Python310\lib\site-packages\pyrogram\errors\rpc_error.py", line 93, in raise_it
    raise getattr(
pyrogram.errors.exceptions.not_acceptable_406.AuthKeyDuplicated: Telegram says: [406 AUTH_KEY_DUPLICATED] (caused by "updates.GetChannelDifference") Pyrogram 2.3.62 thinks: The same authorization key (session file) was used in more than one place simultaneously. You must delete your session file and log in again with your phone number or bot token
[18-May-25 13:33:56 - ERROR] - asyncio - Task exception was never retrieved
future: <Task finished name='Task-1129' coro=<Client.handle_updates() done, defined at C:\Users\aryas\AppData\Local\Programs\Python\Python310\lib\site-packages\pyrogram\client.py:642> exception=AuthKeyDuplicated('Telegram says: [406 AUTH_KEY_DUPLICATED] (caused by "updates.GetChannelDifference") Pyrogram 2.3.62 thinks: The same authorization key (session file) was used in more than one place simultaneously. You must delete your session file and log in again with your phone number or bot token')>
Traceback (most recent call last):
  File "C:\Users\aryas\AppData\Local\Programs\Python\Python310\lib\site-packages\pyrogram\client.py", line 685, in handle_updates
    diff = await self.invoke(
  File "C:\Users\aryas\AppData\Local\Programs\Python\Python310\lib\site-packages\pyrogram\methods\advanced\invoke.py", line 80, in invoke
    r = await self.session.invoke(
  File "C:\Users\aryas\AppData\Local\Programs\Python\Python310\lib\site-packages\pyrogram\session\session.py", line 433, in invoke
    return await self.send(query, timeout=timeout)
  File "C:\Users\aryas\AppData\Local\Programs\Python\Python310\lib\site-packages\pyrogram\session\session.py", line 377, in send
    RPCError.raise_it(result, type(data))
  File "C:\Users\aryas\AppData\Local\Programs\Python\Python310\lib\site-packages\pyrogram\errors\rpc_error.py", line 93, in raise_it
    raise getattr(
pyrogram.errors.exceptions.not_acceptable_406.AuthKeyDuplicated: Telegram says: [406 AUTH_KEY_DUPLICATED] (caused by "updates.GetChannelDifference") Pyrogram 2.3.62 thinks: The same authorization key (session file) was used in more than one place simultaneously. You must delete your session file and log in again with your phone number or bot token
[18-May-25 13:33:56 - ERROR] - asyncio - Task exception was never retrieved
future: <Task finished name='Task-1133' coro=<Client.handle_updates() done, defined at C:\Users\aryas\AppData\Local\Programs\Python\Python310\lib\site-packages\pyrogram\client.py:642> exception=AuthKeyDuplicated('Telegram says: [406 AUTH_KEY_DUPLICATED] (caused by "updates.GetChannelDifference") Pyrogram 2.3.62 thinks: The same authorization key (session file) was used in more than one place simultaneously. You must delete your session file and log in again with your phone number or bot token')>
Traceback (most recent call last):
  File "C:\Users\aryas\AppData\Local\Programs\Python\Python310\lib\site-packages\pyrogram\client.py", line 685, in handle_updates
    diff = await self.invoke(
  File "C:\Users\aryas\AppData\Local\Programs\Python\Python310\lib\site-packages\pyrogram\methods\advanced\invoke.py", line 80, in invoke
    r = await self.session.invoke(
  File "C:\Users\aryas\AppData\Local\Programs\Python\Python310\lib\site-packages\pyrogram\session\session.py", line 433, in invoke
    return await self.send(query, timeout=timeout)
  File "C:\Users\aryas\AppData\Local\Programs\Python\Python310\lib\site-packages\pyrogram\session\session.py", line 377, in send
    RPCError.raise_it(result, type(data))
  File "C:\Users\aryas\AppData\Local\Programs\Python\Python310\lib\site-packages\pyrogram\errors\rpc_error.py", line 93, in raise_it
    raise getattr(
pyrogram.errors.exceptions.not_acceptable_406.AuthKeyDuplicated: Telegram says: [406 AUTH_KEY_DUPLICATED] (caused by "updates.GetChannelDifference") Pyrogram 2.3.62 thinks: The same authorization key (session file) was used in more than one place simultaneously. You must delete your session file and log in again with your phone number or bot token
[18-May-25 13:34:06 - ERROR] - asyncio - Task exception was never retrieved
future: <Task finished name='Task-1175' coro=<Client.handle_updates() done, defined at C:\Users\aryas\AppData\Local\Programs\Python\Python310\lib\site-packages\pyrogram\client.py:642> exception=AuthKeyDuplicated('Telegram says: [406 AUTH_KEY_DUPLICATED] (caused by "updates.GetChannelDifference") Pyrogram 2.3.62 thinks: The same authorization key (session file) was used in more than one place simultaneously. You must delete your session file and log in again with your phone number or bot token')>
Traceback (most recent call last):
  File "C:\Users\aryas\AppData\Local\Programs\Python\Python310\lib\site-packages\pyrogram\client.py", line 685, in handle_updates
    diff = await self.invoke(
  File "C:\Users\aryas\AppData\Local\Programs\Python\Python310\lib\site-packages\pyrogram\methods\advanced\invoke.py", line 80, in invoke
    r = await self.session.invoke(
  File "C:\Users\aryas\AppData\Local\Programs\Python\Python310\lib\site-packages\pyrogram\session\session.py", line 433, in invoke
    return await self.send(query, timeout=timeout)
  File "C:\Users\aryas\AppData\Local\Programs\Python\Python310\lib\site-packages\pyrogram\session\session.py", line 377, in send
    RPCError.raise_it(result, type(data))
  File "C:\Users\aryas\AppData\Local\Programs\Python\Python310\lib\site-packages\pyrogram\errors\rpc_error.py", line 93, in raise_it
    raise getattr(
pyrogram.errors.exceptions.not_acceptable_406.AuthKeyDuplicated: Telegram says: [406 AUTH_KEY_DUPLICATED] (caused by "updates.GetChannelDifference") Pyrogram 2.3.62 thinks: The same authorization key (session file) was used in more than one place simultaneously. You must delete your session file and log in again with your phone number or bot token
[18-May-25 13:34:11 - ERROR] - asyncio - Task exception was never retrieved
future: <Task finished name='Task-1193' coro=<Client.handle_updates() done, defined at C:\Users\aryas\AppData\Local\Programs\Python\Python310\lib\site-packages\pyrogram\client.py:642> exception=AuthKeyDuplicated('Telegram says: [406 AUTH_KEY_DUPLICATED] (caused by "updates.GetChannelDifference") Pyrogram 2.3.62 thinks: The same authorization key (session file) was used in more than one place simultaneously. You must delete your session file and log in again with your phone number or bot token')>
Traceback (most recent call last):
  File "C:\Users\aryas\AppData\Local\Programs\Python\Python310\lib\site-packages\pyrogram\client.py", line 685, in handle_updates
    diff = await self.invoke(
  File "C:\Users\aryas\AppData\Local\Programs\Python\Python310\lib\site-packages\pyrogram\methods\advanced\invoke.py", line 80, in invoke
    r = await self.session.invoke(
  File "C:\Users\aryas\AppData\Local\Programs\Python\Python310\lib\site-packages\pyrogram\session\session.py", line 433, in invoke
    return await self.send(query, timeout=timeout)
  File "C:\Users\aryas\AppData\Local\Programs\Python\Python310\lib\site-packages\pyrogram\session\session.py", line 377, in send
    RPCError.raise_it(result, type(data))
  File "C:\Users\aryas\AppData\Local\Programs\Python\Python310\lib\site-packages\pyrogram\errors\rpc_error.py", line 93, in raise_it
    raise getattr(
pyrogram.errors.exceptions.not_acceptable_406.AuthKeyDuplicated: Telegram says: [406 AUTH_KEY_DUPLICATED] (caused by "updates.GetChannelDifference") Pyrogram 2.3.62 thinks: The same authorization key (session file) was used in more than one place simultaneously. You must delete your session file and log in again with your phone number or bot token
[18-May-25 13:34:21 - ERROR] - asyncio - Task exception was never retrieved
future: <Task finished name='Task-1223' coro=<Client.handle_updates() done, defined at C:\Users\aryas\AppData\Local\Programs\Python\Python310\lib\site-packages\pyrogram\client.py:642> exception=AuthKeyDuplicated('Telegram says: [406 AUTH_KEY_DUPLICATED] (caused by "updates.GetChannelDifference") Pyrogram 2.3.62 thinks: The same authorization key (session file) was used in more than one place simultaneously. You must delete your session file and log in again with your phone number or bot token')>
Traceback (most recent call last):
  File "C:\Users\aryas\AppData\Local\Programs\Python\Python310\lib\site-packages\pyrogram\client.py", line 685, in handle_updates
    diff = await self.invoke(
  File "C:\Users\aryas\AppData\Local\Programs\Python\Python310\lib\site-packages\pyrogram\methods\advanced\invoke.py", line 80, in invoke
    r = await self.session.invoke(
  File "C:\Users\aryas\AppData\Local\Programs\Python\Python310\lib\site-packages\pyrogram\session\session.py", line 433, in invoke
    return await self.send(query, timeout=timeout)
  File "C:\Users\aryas\AppData\Local\Programs\Python\Python310\lib\site-packages\pyrogram\session\session.py", line 377, in send
    RPCError.raise_it(result, type(data))
  File "C:\Users\aryas\AppData\Local\Programs\Python\Python310\lib\site-packages\pyrogram\errors\rpc_error.py", line 93, in raise_it
    raise getattr(
pyrogram.errors.exceptions.not_acceptable_406.AuthKeyDuplicated: Telegram says: [406 AUTH_KEY_DUPLICATED] (caused by "updates.GetChannelDifference") Pyrogram 2.3.62 thinks: The same authorization key (session file) was used in more than one place simultaneously. You must delete your session file and log in again with your phone number or bot token
[18-May-25 13:34:31 - ERROR] - asyncio - Task exception was never retrieved
future: <Task finished name='Task-1254' coro=<Client.handle_updates() done, defined at C:\Users\aryas\AppData\Local\Programs\Python\Python310\lib\site-packages\pyrogram\client.py:642> exception=AuthKeyDuplicated('Telegram says: [406 AUTH_KEY_DUPLICATED] (caused by "updates.GetChannelDifference") Pyrogram 2.3.62 thinks: The same authorization key (session file) was used in more than one place simultaneously. You must delete your session file and log in again with your phone number or bot token')>
Traceback (most recent call last):
  File "C:\Users\aryas\AppData\Local\Programs\Python\Python310\lib\site-packages\pyrogram\client.py", line 685, in handle_updates
    diff = await self.invoke(
  File "C:\Users\aryas\AppData\Local\Programs\Python\Python310\lib\site-packages\pyrogram\methods\advanced\invoke.py", line 80, in invoke
    r = await self.session.invoke(
  File "C:\Users\aryas\AppData\Local\Programs\Python\Python310\lib\site-packages\pyrogram\session\session.py", line 433, in invoke
    return await self.send(query, timeout=timeout)
  File "C:\Users\aryas\AppData\Local\Programs\Python\Python310\lib\site-packages\pyrogram\session\session.py", line 377, in send
    RPCError.raise_it(result, type(data))
  File "C:\Users\aryas\AppData\Local\Programs\Python\Python310\lib\site-packages\pyrogram\errors\rpc_error.py", line 93, in raise_it
    raise getattr(
pyrogram.errors.exceptions.not_acceptable_406.AuthKeyDuplicated: Telegram says: [406 AUTH_KEY_DUPLICATED] (caused by "updates.GetChannelDifference") Pyrogram 2.3.62 thinks: The same authorization key (session file) was used in more than one place simultaneously. You must delete your session file and log in again with your phone number or bot token
[18-May-25 13:34:31 - ERROR] - asyncio - Task exception was never retrieved
future: <Task finished name='Task-1255' coro=<Client.handle_updates() done, defined at C:\Users\aryas\AppData\Local\Programs\Python\Python310\lib\site-packages\pyrogram\client.py:642> exception=AuthKeyDuplicated('Telegram says: [406 AUTH_KEY_DUPLICATED] (caused by "updates.GetChannelDifference") Pyrogram 2.3.62 thinks: The same authorization key (session file) was used in more than one place simultaneously. You must delete your session file and log in again with your phone number or bot token')>
Traceback (most recent call last):
  File "C:\Users\aryas\AppData\Local\Programs\Python\Python310\lib\site-packages\pyrogram\client.py", line 685, in handle_updates
    diff = await self.invoke(
  File "C:\Users\aryas\AppData\Local\Programs\Python\Python310\lib\site-packages\pyrogram\methods\advanced\invoke.py", line 80, in invoke
    r = await self.session.invoke(
  File "C:\Users\aryas\AppData\Local\Programs\Python\Python310\lib\site-packages\pyrogram\session\session.py", line 433, in invoke
    return await self.send(query, timeout=timeout)
  File "C:\Users\aryas\AppData\Local\Programs\Python\Python310\lib\site-packages\pyrogram\session\session.py", line 377, in send
    RPCError.raise_it(result, type(data))
  File "C:\Users\aryas\AppData\Local\Programs\Python\Python310\lib\site-packages\pyrogram\errors\rpc_error.py", line 93, in raise_it
    raise getattr(
pyrogram.errors.exceptions.not_acceptable_406.AuthKeyDuplicated: Telegram says: [406 AUTH_KEY_DUPLICATED] (caused by "updates.GetChannelDifference") Pyrogram 2.3.62 thinks: The same authorization key (session file) was used in more than one place simultaneously. You must delete your session file and log in again with your phone number or bot token
[18-May-25 13:34:36 - ERROR] - asyncio - Task exception was never retrieved
future: <Task finished name='Task-1280' coro=<Client.handle_updates() done, defined at C:\Users\aryas\AppData\Local\Programs\Python\Python310\lib\site-packages\pyrogram\client.py:642> exception=AuthKeyDuplicated('Telegram says: [406 AUTH_KEY_DUPLICATED] (caused by "updates.GetChannelDifference") Pyrogram 2.3.62 thinks: The same authorization key (session file) was used in more than one place simultaneously. You must delete your session file and log in again with your phone number or bot token')>
Traceback (most recent call last):
  File "C:\Users\aryas\AppData\Local\Programs\Python\Python310\lib\site-packages\pyrogram\client.py", line 685, in handle_updates
    diff = await self.invoke(
  File "C:\Users\aryas\AppData\Local\Programs\Python\Python310\lib\site-packages\pyrogram\methods\advanced\invoke.py", line 80, in invoke
    r = await self.session.invoke(
  File "C:\Users\aryas\AppData\Local\Programs\Python\Python310\lib\site-packages\pyrogram\session\session.py", line 433, in invoke
    return await self.send(query, timeout=timeout)
  File "C:\Users\aryas\AppData\Local\Programs\Python\Python310\lib\site-packages\pyrogram\session\session.py", line 377, in send
    RPCError.raise_it(result, type(data))
  File "C:\Users\aryas\AppData\Local\Programs\Python\Python310\lib\site-packages\pyrogram\errors\rpc_error.py", line 93, in raise_it
    raise getattr(
pyrogram.errors.exceptions.not_acceptable_406.AuthKeyDuplicated: Telegram says: [406 AUTH_KEY_DUPLICATED] (caused by "updates.GetChannelDifference") Pyrogram 2.3.62 thinks: The same authorization key (session file) was used in more than one place simultaneously. You must delete your session file and log in again with your phone number or bot token
[18-May-25 13:34:41 - ERROR] - asyncio - Task exception was never retrieved
future: <Task finished name='Task-1298' coro=<Client.handle_updates() done, defined at C:\Users\aryas\AppData\Local\Programs\Python\Python310\lib\site-packages\pyrogram\client.py:642> exception=AuthKeyDuplicated('Telegram says: [406 AUTH_KEY_DUPLICATED] (caused by "updates.GetChannelDifference") Pyrogram 2.3.62 thinks: The same authorization key (session file) was used in more than one place simultaneously. You must delete your session file and log in again with your phone number or bot token')>
Traceback (most recent call last):
  File "C:\Users\aryas\AppData\Local\Programs\Python\Python310\lib\site-packages\pyrogram\client.py", line 685, in handle_updates
    diff = await self.invoke(
  File "C:\Users\aryas\AppData\Local\Programs\Python\Python310\lib\site-packages\pyrogram\methods\advanced\invoke.py", line 80, in invoke
    r = await self.session.invoke(
  File "C:\Users\aryas\AppData\Local\Programs\Python\Python310\lib\site-packages\pyrogram\session\session.py", line 433, in invoke
    return await self.send(query, timeout=timeout)
  File "C:\Users\aryas\AppData\Local\Programs\Python\Python310\lib\site-packages\pyrogram\session\session.py", line 377, in send
    RPCError.raise_it(result, type(data))
  File "C:\Users\aryas\AppData\Local\Programs\Python\Python310\lib\site-packages\pyrogram\errors\rpc_error.py", line 93, in raise_it
    raise getattr(
pyrogram.errors.exceptions.not_acceptable_406.AuthKeyDuplicated: Telegram says: [406 AUTH_KEY_DUPLICATED] (caused by "updates.GetChannelDifference") Pyrogram 2.3.62 thinks: The same authorization key (session file) was used in more than one place simultaneously. You must delete your session file and log in again with your phone number or bot token
[18-May-25 13:34:46 - ERROR] - asyncio - Task exception was never retrieved
future: <Task finished name='Task-1333' coro=<Client.handle_updates() done, defined at C:\Users\aryas\AppData\Local\Programs\Python\Python310\lib\site-packages\pyrogram\client.py:642> exception=AuthKeyDuplicated('Telegram says: [406 AUTH_KEY_DUPLICATED] (caused by "updates.GetChannelDifference") Pyrogram 2.3.62 thinks: The same authorization key (session file) was used in more than one place simultaneously. You must delete your session file and log in again with your phone number or bot token')>
Traceback (most recent call last):
  File "C:\Users\aryas\AppData\Local\Programs\Python\Python310\lib\site-packages\pyrogram\client.py", line 685, in handle_updates
    diff = await self.invoke(
  File "C:\Users\aryas\AppData\Local\Programs\Python\Python310\lib\site-packages\pyrogram\methods\advanced\invoke.py", line 80, in invoke
    r = await self.session.invoke(
  File "C:\Users\aryas\AppData\Local\Programs\Python\Python310\lib\site-packages\pyrogram\session\session.py", line 433, in invoke
    return await self.send(query, timeout=timeout)
  File "C:\Users\aryas\AppData\Local\Programs\Python\Python310\lib\site-packages\pyrogram\session\session.py", line 377, in send
    RPCError.raise_it(result, type(data))
  File "C:\Users\aryas\AppData\Local\Programs\Python\Python310\lib\site-packages\pyrogram\errors\rpc_error.py", line 93, in raise_it
    raise getattr(
pyrogram.errors.exceptions.not_acceptable_406.AuthKeyDuplicated: Telegram says: [406 AUTH_KEY_DUPLICATED] (caused by "updates.GetChannelDifference") Pyrogram 2.3.62 thinks: The same authorization key (session file) was used in more than one place simultaneously. You must delete your session file and log in again with your phone number or bot token
[18-May-25 13:34:46 - ERROR] - asyncio - Task exception was never retrieved
future: <Task finished name='Task-1329' coro=<Client.handle_updates() done, defined at C:\Users\aryas\AppData\Local\Programs\Python\Python310\lib\site-packages\pyrogram\client.py:642> exception=AuthKeyDuplicated('Telegram says: [406 AUTH_KEY_DUPLICATED] (caused by "updates.GetChannelDifference") Pyrogram 2.3.62 thinks: The same authorization key (session file) was used in more than one place simultaneously. You must delete your session file and log in again with your phone number or bot token')>
Traceback (most recent call last):
  File "C:\Users\aryas\AppData\Local\Programs\Python\Python310\lib\site-packages\pyrogram\client.py", line 685, in handle_updates
    diff = await self.invoke(
  File "C:\Users\aryas\AppData\Local\Programs\Python\Python310\lib\site-packages\pyrogram\methods\advanced\invoke.py", line 80, in invoke
    r = await self.session.invoke(
  File "C:\Users\aryas\AppData\Local\Programs\Python\Python310\lib\site-packages\pyrogram\session\session.py", line 433, in invoke
    return await self.send(query, timeout=timeout)
  File "C:\Users\aryas\AppData\Local\Programs\Python\Python310\lib\site-packages\pyrogram\session\session.py", line 377, in send
    RPCError.raise_it(result, type(data))
  File "C:\Users\aryas\AppData\Local\Programs\Python\Python310\lib\site-packages\pyrogram\errors\rpc_error.py", line 93, in raise_it
    raise getattr(
pyrogram.errors.exceptions.not_acceptable_406.AuthKeyDuplicated: Telegram says: [406 AUTH_KEY_DUPLICATED] (caused by "updates.GetChannelDifference") Pyrogram 2.3.62 thinks: The same authorization key (session file) was used in more than one place simultaneously. You must delete your session file and log in again with your phone number or bot token
[18-May-25 13:34:46 - ERROR] - asyncio - Task exception was never retrieved
future: <Task finished name='Task-1331' coro=<Client.handle_updates() done, defined at C:\Users\aryas\AppData\Local\Programs\Python\Python310\lib\site-packages\pyrogram\client.py:642> exception=AuthKeyDuplicated('Telegram says: [406 AUTH_KEY_DUPLICATED] (caused by "updates.GetChannelDifference") Pyrogram 2.3.62 thinks: The same authorization key (session file) was used in more than one place simultaneously. You must delete your session file and log in again with your phone number or bot token')>
Traceback (most recent call last):
  File "C:\Users\aryas\AppData\Local\Programs\Python\Python310\lib\site-packages\pyrogram\client.py", line 685, in handle_updates
    diff = await self.invoke(
  File "C:\Users\aryas\AppData\Local\Programs\Python\Python310\lib\site-packages\pyrogram\methods\advanced\invoke.py", line 80, in invoke
    r = await self.session.invoke(
  File "C:\Users\aryas\AppData\Local\Programs\Python\Python310\lib\site-packages\pyrogram\session\session.py", line 433, in invoke
    return await self.send(query, timeout=timeout)
  File "C:\Users\aryas\AppData\Local\Programs\Python\Python310\lib\site-packages\pyrogram\session\session.py", line 377, in send
    RPCError.raise_it(result, type(data))
  File "C:\Users\aryas\AppData\Local\Programs\Python\Python310\lib\site-packages\pyrogram\errors\rpc_error.py", line 93, in raise_it
    raise getattr(
pyrogram.errors.exceptions.not_acceptable_406.AuthKeyDuplicated: Telegram says: [406 AUTH_KEY_DUPLICATED] (caused by "updates.GetChannelDifference") Pyrogram 2.3.62 thinks: The same authorization key (session file) was used in more than one place simultaneously. You must delete your session file and log in again with your phone number or bot token
[18-May-25 13:34:46 - ERROR] - asyncio - Task exception was never retrieved
future: <Task finished name='Task-1337' coro=<Client.handle_updates() done, defined at C:\Users\aryas\AppData\Local\Programs\Python\Python310\lib\site-packages\pyrogram\client.py:642> exception=AuthKeyDuplicated('Telegram says: [406 AUTH_KEY_DUPLICATED] (caused by "updates.GetChannelDifference") Pyrogram 2.3.62 thinks: The same authorization key (session file) was used in more than one place simultaneously. You must delete your session file and log in again with your phone number or bot token')>
Traceback (most recent call last):
  File "C:\Users\aryas\AppData\Local\Programs\Python\Python310\lib\site-packages\pyrogram\client.py", line 685, in handle_updates
    diff = await self.invoke(
  File "C:\Users\aryas\AppData\Local\Programs\Python\Python310\lib\site-packages\pyrogram\methods\advanced\invoke.py", line 80, in invoke
    r = await self.session.invoke(
  File "C:\Users\aryas\AppData\Local\Programs\Python\Python310\lib\site-packages\pyrogram\session\session.py", line 433, in invoke
    return await self.send(query, timeout=timeout)
  File "C:\Users\aryas\AppData\Local\Programs\Python\Python310\lib\site-packages\pyrogram\session\session.py", line 377, in send
    RPCError.raise_it(result, type(data))
  File "C:\Users\aryas\AppData\Local\Programs\Python\Python310\lib\site-packages\pyrogram\errors\rpc_error.py", line 93, in raise_it
    raise getattr(
pyrogram.errors.exceptions.not_acceptable_406.AuthKeyDuplicated: Telegram says: [406 AUTH_KEY_DUPLICATED] (caused by "updates.GetChannelDifference") Pyrogram 2.3.62 thinks: The same authorization key (session file) was used in more than one place simultaneously. You must delete your session file and log in again with your phone number or bot token
[18-May-25 13:34:46 - ERROR] - asyncio - Task exception was never retrieved
future: <Task finished name='Task-1338' coro=<Client.handle_updates() done, defined at C:\Users\aryas\AppData\Local\Programs\Python\Python310\lib\site-packages\pyrogram\client.py:642> exception=AuthKeyDuplicated('Telegram says: [406 AUTH_KEY_DUPLICATED] (caused by "updates.GetChannelDifference") Pyrogram 2.3.62 thinks: The same authorization key (session file) was used in more than one place simultaneously. You must delete your session file and log in again with your phone number or bot token')>
Traceback (most recent call last):
  File "C:\Users\aryas\AppData\Local\Programs\Python\Python310\lib\site-packages\pyrogram\client.py", line 685, in handle_updates
    diff = await self.invoke(
  File "C:\Users\aryas\AppData\Local\Programs\Python\Python310\lib\site-packages\pyrogram\methods\advanced\invoke.py", line 80, in invoke
    r = await self.session.invoke(
  File "C:\Users\aryas\AppData\Local\Programs\Python\Python310\lib\site-packages\pyrogram\session\session.py", line 433, in invoke
    return await self.send(query, timeout=timeout)
  File "C:\Users\aryas\AppData\Local\Programs\Python\Python310\lib\site-packages\pyrogram\session\session.py", line 377, in send
    RPCError.raise_it(result, type(data))
  File "C:\Users\aryas\AppData\Local\Programs\Python\Python310\lib\site-packages\pyrogram\errors\rpc_error.py", line 93, in raise_it
    raise getattr(
pyrogram.errors.exceptions.not_acceptable_406.AuthKeyDuplicated: Telegram says: [406 AUTH_KEY_DUPLICATED] (caused by "updates.GetChannelDifference") Pyrogram 2.3.62 thinks: The same authorization key (session file) was used in more than one place simultaneously. You must delete your session file and log in again with your phone number or bot token
[18-May-25 13:34:56 - ERROR] - asyncio - Task exception was never retrieved
future: <Task finished name='Task-1397' coro=<Client.handle_updates() done, defined at C:\Users\aryas\AppData\Local\Programs\Python\Python310\lib\site-packages\pyrogram\client.py:642> exception=AuthKeyDuplicated('Telegram says: [406 AUTH_KEY_DUPLICATED] (caused by "updates.GetChannelDifference") Pyrogram 2.3.62 thinks: The same authorization key (session file) was used in more than one place simultaneously. You must delete your session file and log in again with your phone number or bot token')>
Traceback (most recent call last):
  File "C:\Users\aryas\AppData\Local\Programs\Python\Python310\lib\site-packages\pyrogram\client.py", line 685, in handle_updates
    diff = await self.invoke(
  File "C:\Users\aryas\AppData\Local\Programs\Python\Python310\lib\site-packages\pyrogram\methods\advanced\invoke.py", line 80, in invoke
    r = await self.session.invoke(
  File "C:\Users\aryas\AppData\Local\Programs\Python\Python310\lib\site-packages\pyrogram\session\session.py", line 433, in invoke
    return await self.send(query, timeout=timeout)
  File "C:\Users\aryas\AppData\Local\Programs\Python\Python310\lib\site-packages\pyrogram\session\session.py", line 377, in send
    RPCError.raise_it(result, type(data))
  File "C:\Users\aryas\AppData\Local\Programs\Python\Python310\lib\site-packages\pyrogram\errors\rpc_error.py", line 93, in raise_it
    raise getattr(
pyrogram.errors.exceptions.not_acceptable_406.AuthKeyDuplicated: Telegram says: [406 AUTH_KEY_DUPLICATED] (caused by "updates.GetChannelDifference") Pyrogram 2.3.62 thinks: The same authorization key (session file) was used in more than one place simultaneously. You must delete your session file and log in again with your phone number or bot token
[18-May-25 13:34:56 - ERROR] - asyncio - Task exception was never retrieved
future: <Task finished name='Task-1396' coro=<Client.handle_updates() done, defined at C:\Users\aryas\AppData\Local\Programs\Python\Python310\lib\site-packages\pyrogram\client.py:642> exception=AuthKeyDuplicated('Telegram says: [406 AUTH_KEY_DUPLICATED] (caused by "updates.GetChannelDifference") Pyrogram 2.3.62 thinks: The same authorization key (session file) was used in more than one place simultaneously. You must delete your session file and log in again with your phone number or bot token')>
Traceback (most recent call last):
  File "C:\Users\aryas\AppData\Local\Programs\Python\Python310\lib\site-packages\pyrogram\client.py", line 685, in handle_updates
    diff = await self.invoke(
  File "C:\Users\aryas\AppData\Local\Programs\Python\Python310\lib\site-packages\pyrogram\methods\advanced\invoke.py", line 80, in invoke
    r = await self.session.invoke(
  File "C:\Users\aryas\AppData\Local\Programs\Python\Python310\lib\site-packages\pyrogram\session\session.py", line 433, in invoke
    return await self.send(query, timeout=timeout)
  File "C:\Users\aryas\AppData\Local\Programs\Python\Python310\lib\site-packages\pyrogram\session\session.py", line 377, in send
    RPCError.raise_it(result, type(data))
  File "C:\Users\aryas\AppData\Local\Programs\Python\Python310\lib\site-packages\pyrogram\errors\rpc_error.py", line 93, in raise_it
    raise getattr(
pyrogram.errors.exceptions.not_acceptable_406.AuthKeyDuplicated: Telegram says: [406 AUTH_KEY_DUPLICATED] (caused by "updates.GetChannelDifference") Pyrogram 2.3.62 thinks: The same authorization key (session file) was used in more than one place simultaneously. You must delete your session file and log in again with your phone number or bot token
[18-May-25 13:34:56 - ERROR] - asyncio - Task exception was never retrieved
future: <Task finished name='Task-1398' coro=<Client.handle_updates() done, defined at C:\Users\aryas\AppData\Local\Programs\Python\Python310\lib\site-packages\pyrogram\client.py:642> exception=AuthKeyDuplicated('Telegram says: [406 AUTH_KEY_DUPLICATED] (caused by "updates.GetChannelDifference") Pyrogram 2.3.62 thinks: The same authorization key (session file) was used in more than one place simultaneously. You must delete your session file and log in again with your phone number or bot token')>
Traceback (most recent call last):
  File "C:\Users\aryas\AppData\Local\Programs\Python\Python310\lib\site-packages\pyrogram\client.py", line 685, in handle_updates
    diff = await self.invoke(
  File "C:\Users\aryas\AppData\Local\Programs\Python\Python310\lib\site-packages\pyrogram\methods\advanced\invoke.py", line 80, in invoke
    r = await self.session.invoke(
  File "C:\Users\aryas\AppData\Local\Programs\Python\Python310\lib\site-packages\pyrogram\session\session.py", line 433, in invoke
    return await self.send(query, timeout=timeout)
  File "C:\Users\aryas\AppData\Local\Programs\Python\Python310\lib\site-packages\pyrogram\session\session.py", line 377, in send
    RPCError.raise_it(result, type(data))
  File "C:\Users\aryas\AppData\Local\Programs\Python\Python310\lib\site-packages\pyrogram\errors\rpc_error.py", line 93, in raise_it
    raise getattr(
pyrogram.errors.exceptions.not_acceptable_406.AuthKeyDuplicated: Telegram says: [406 AUTH_KEY_DUPLICATED] (caused by "updates.GetChannelDifference") Pyrogram 2.3.62 thinks: The same authorization key (session file) was used in more than one place simultaneously. You must delete your session file and log in again with your phone number or bot token
[18-May-25 13:35:21 - ERROR] - asyncio - Task exception was never retrieved
future: <Task finished name='Task-1476' coro=<Client.handle_updates() done, defined at C:\Users\aryas\AppData\Local\Programs\Python\Python310\lib\site-packages\pyrogram\client.py:642> exception=AuthKeyDuplicated('Telegram says: [406 AUTH_KEY_DUPLICATED] (caused by "updates.GetChannelDifference") Pyrogram 2.3.62 thinks: The same authorization key (session file) was used in more than one place simultaneously. You must delete your session file and log in again with your phone number or bot token')>
Traceback (most recent call last):
  File "C:\Users\aryas\AppData\Local\Programs\Python\Python310\lib\site-packages\pyrogram\client.py", line 685, in handle_updates
    diff = await self.invoke(
  File "C:\Users\aryas\AppData\Local\Programs\Python\Python310\lib\site-packages\pyrogram\methods\advanced\invoke.py", line 80, in invoke
    r = await self.session.invoke(
  File "C:\Users\aryas\AppData\Local\Programs\Python\Python310\lib\site-packages\pyrogram\session\session.py", line 433, in invoke
    return await self.send(query, timeout=timeout)
  File "C:\Users\aryas\AppData\Local\Programs\Python\Python310\lib\site-packages\pyrogram\session\session.py", line 377, in send
    RPCError.raise_it(result, type(data))
  File "C:\Users\aryas\AppData\Local\Programs\Python\Python310\lib\site-packages\pyrogram\errors\rpc_error.py", line 93, in raise_it
    raise getattr(
pyrogram.errors.exceptions.not_acceptable_406.AuthKeyDuplicated: Telegram says: [406 AUTH_KEY_DUPLICATED] (caused by "updates.GetChannelDifference") Pyrogram 2.3.62 thinks: The same authorization key (session file) was used in more than one place simultaneously. You must delete your session file and log in again with your phone number or bot token
[18-May-25 13:35:57 - ERROR] - asyncio - Task exception was never retrieved
future: <Task finished name='Task-1565' coro=<Client.handle_updates() done, defined at C:\Users\aryas\AppData\Local\Programs\Python\Python310\lib\site-packages\pyrogram\client.py:642> exception=AuthKeyDuplicated('Telegram says: [406 AUTH_KEY_DUPLICATED] (caused by "updates.GetChannelDifference") Pyrogram 2.3.62 thinks: The same authorization key (session file) was used in more than one place simultaneously. You must delete your session file and log in again with your phone number or bot token')>
Traceback (most recent call last):
  File "C:\Users\aryas\AppData\Local\Programs\Python\Python310\lib\site-packages\pyrogram\client.py", line 685, in handle_updates
    diff = await self.invoke(
  File "C:\Users\aryas\AppData\Local\Programs\Python\Python310\lib\site-packages\pyrogram\methods\advanced\invoke.py", line 80, in invoke
    r = await self.session.invoke(
  File "C:\Users\aryas\AppData\Local\Programs\Python\Python310\lib\site-packages\pyrogram\session\session.py", line 433, in invoke
    return await self.send(query, timeout=timeout)
  File "C:\Users\aryas\AppData\Local\Programs\Python\Python310\lib\site-packages\pyrogram\session\session.py", line 377, in send
    RPCError.raise_it(result, type(data))
  File "C:\Users\aryas\AppData\Local\Programs\Python\Python310\lib\site-packages\pyrogram\errors\rpc_error.py", line 93, in raise_it
    raise getattr(
pyrogram.errors.exceptions.not_acceptable_406.AuthKeyDuplicated: Telegram says: [406 AUTH_KEY_DUPLICATED] (caused by "updates.GetChannelDifference") Pyrogram 2.3.62 thinks: The same authorization key (session file) was used in more than one place simultaneously. You must delete your session file and log in again with your phone number or bot token
[18-May-25 13:36:06 - ERROR] - asyncio - Task exception was never retrieved
future: <Task finished name='Task-1607' coro=<Client.handle_updates() done, defined at C:\Users\aryas\AppData\Local\Programs\Python\Python310\lib\site-packages\pyrogram\client.py:642> exception=AuthKeyDuplicated('Telegram says: [406 AUTH_KEY_DUPLICATED] (caused by "updates.GetChannelDifference") Pyrogram 2.3.62 thinks: The same authorization key (session file) was used in more than one place simultaneously. You must delete your session file and log in again with your phone number or bot token')>
Traceback (most recent call last):
  File "C:\Users\aryas\AppData\Local\Programs\Python\Python310\lib\site-packages\pyrogram\client.py", line 685, in handle_updates
    diff = await self.invoke(
  File "C:\Users\aryas\AppData\Local\Programs\Python\Python310\lib\site-packages\pyrogram\methods\advanced\invoke.py", line 80, in invoke
    r = await self.session.invoke(
  File "C:\Users\aryas\AppData\Local\Programs\Python\Python310\lib\site-packages\pyrogram\session\session.py", line 433, in invoke
    return await self.send(query, timeout=timeout)
  File "C:\Users\aryas\AppData\Local\Programs\Python\Python310\lib\site-packages\pyrogram\session\session.py", line 377, in send
    RPCError.raise_it(result, type(data))
  File "C:\Users\aryas\AppData\Local\Programs\Python\Python310\lib\site-packages\pyrogram\errors\rpc_error.py", line 93, in raise_it
    raise getattr(
pyrogram.errors.exceptions.not_acceptable_406.AuthKeyDuplicated: Telegram says: [406 AUTH_KEY_DUPLICATED] (caused by "updates.GetChannelDifference") Pyrogram 2.3.62 thinks: The same authorization key (session file) was used in more than one place simultaneously. You must delete your session file and log in again with your phone number or bot token
[18-May-25 13:36:06 - ERROR] - asyncio - Task exception was never retrieved
future: <Task finished name='Task-1609' coro=<Client.handle_updates() done, defined at C:\Users\aryas\AppData\Local\Programs\Python\Python310\lib\site-packages\pyrogram\client.py:642> exception=AuthKeyDuplicated('Telegram says: [406 AUTH_KEY_DUPLICATED] (caused by "updates.GetChannelDifference") Pyrogram 2.3.62 thinks: The same authorization key (session file) was used in more than one place simultaneously. You must delete your session file and log in again with your phone number or bot token')>
Traceback (most recent call last):
  File "C:\Users\aryas\AppData\Local\Programs\Python\Python310\lib\site-packages\pyrogram\client.py", line 685, in handle_updates
    diff = await self.invoke(
  File "C:\Users\aryas\AppData\Local\Programs\Python\Python310\lib\site-packages\pyrogram\methods\advanced\invoke.py", line 80, in invoke
    r = await self.session.invoke(
  File "C:\Users\aryas\AppData\Local\Programs\Python\Python310\lib\site-packages\pyrogram\session\session.py", line 433, in invoke
    return await self.send(query, timeout=timeout)
  File "C:\Users\aryas\AppData\Local\Programs\Python\Python310\lib\site-packages\pyrogram\session\session.py", line 377, in send
    RPCError.raise_it(result, type(data))
  File "C:\Users\aryas\AppData\Local\Programs\Python\Python310\lib\site-packages\pyrogram\errors\rpc_error.py", line 93, in raise_it
    raise getattr(
pyrogram.errors.exceptions.not_acceptable_406.AuthKeyDuplicated: Telegram says: [406 AUTH_KEY_DUPLICATED] (caused by "updates.GetChannelDifference") Pyrogram 2.3.62 thinks: The same authorization key (session file) was used in more than one place simultaneously. You must delete your session file and log in again with your phone number or bot token
[18-May-25 13:36:06 - ERROR] - asyncio - Task exception was never retrieved
future: <Task finished name='Task-1608' coro=<Client.handle_updates() done, defined at C:\Users\aryas\AppData\Local\Programs\Python\Python310\lib\site-packages\pyrogram\client.py:642> exception=AuthKeyDuplicated('Telegram says: [406 AUTH_KEY_DUPLICATED] (caused by "updates.GetChannelDifference") Pyrogram 2.3.62 thinks: The same authorization key (session file) was used in more than one place simultaneously. You must delete your session file and log in again with your phone number or bot token')>
Traceback (most recent call last):
  File "C:\Users\aryas\AppData\Local\Programs\Python\Python310\lib\site-packages\pyrogram\client.py", line 685, in handle_updates
    diff = await self.invoke(
  File "C:\Users\aryas\AppData\Local\Programs\Python\Python310\lib\site-packages\pyrogram\methods\advanced\invoke.py", line 80, in invoke
    r = await self.session.invoke(
  File "C:\Users\aryas\AppData\Local\Programs\Python\Python310\lib\site-packages\pyrogram\session\session.py", line 433, in invoke
    return await self.send(query, timeout=timeout)
  File "C:\Users\aryas\AppData\Local\Programs\Python\Python310\lib\site-packages\pyrogram\session\session.py", line 377, in send
    RPCError.raise_it(result, type(data))
  File "C:\Users\aryas\AppData\Local\Programs\Python\Python310\lib\site-packages\pyrogram\errors\rpc_error.py", line 93, in raise_it
    raise getattr(
pyrogram.errors.exceptions.not_acceptable_406.AuthKeyDuplicated: Telegram says: [406 AUTH_KEY_DUPLICATED] (caused by "updates.GetChannelDifference") Pyrogram 2.3.62 thinks: The same authorization key (session file) was used in more than one place simultaneously. You must delete your session file and log in again with your phone number or bot token
[18-May-25 13:36:11 - ERROR] - asyncio - Task exception was never retrieved
future: <Task finished name='Task-1641' coro=<Client.handle_updates() done, defined at C:\Users\aryas\AppData\Local\Programs\Python\Python310\lib\site-packages\pyrogram\client.py:642> exception=AuthKeyDuplicated('Telegram says: [406 AUTH_KEY_DUPLICATED] (caused by "updates.GetChannelDifference") Pyrogram 2.3.62 thinks: The same authorization key (session file) was used in more than one place simultaneously. You must delete your session file and log in again with your phone number or bot token')>
Traceback (most recent call last):
  File "C:\Users\aryas\AppData\Local\Programs\Python\Python310\lib\site-packages\pyrogram\client.py", line 685, in handle_updates
    diff = await self.invoke(
  File "C:\Users\aryas\AppData\Local\Programs\Python\Python310\lib\site-packages\pyrogram\methods\advanced\invoke.py", line 80, in invoke
    r = await self.session.invoke(
  File "C:\Users\aryas\AppData\Local\Programs\Python\Python310\lib\site-packages\pyrogram\session\session.py", line 433, in invoke
    return await self.send(query, timeout=timeout)
  File "C:\Users\aryas\AppData\Local\Programs\Python\Python310\lib\site-packages\pyrogram\session\session.py", line 377, in send
    RPCError.raise_it(result, type(data))
  File "C:\Users\aryas\AppData\Local\Programs\Python\Python310\lib\site-packages\pyrogram\errors\rpc_error.py", line 93, in raise_it
    raise getattr(
pyrogram.errors.exceptions.not_acceptable_406.AuthKeyDuplicated: Telegram says: [406 AUTH_KEY_DUPLICATED] (caused by "updates.GetChannelDifference") Pyrogram 2.3.62 thinks: The same authorization key (session file) was used in more than one place simultaneously. You must delete your session file and log in again with your phone number or bot token
[18-May-25 13:36:21 - ERROR] - asyncio - Task exception was never retrieved
future: <Task finished name='Task-1672' coro=<Client.handle_updates() done, defined at C:\Users\aryas\AppData\Local\Programs\Python\Python310\lib\site-packages\pyrogram\client.py:642> exception=AuthKeyDuplicated('Telegram says: [406 AUTH_KEY_DUPLICATED] (caused by "updates.GetChannelDifference") Pyrogram 2.3.62 thinks: The same authorization key (session file) was used in more than one place simultaneously. You must delete your session file and log in again with your phone number or bot token')>
Traceback (most recent call last):
  File "C:\Users\aryas\AppData\Local\Programs\Python\Python310\lib\site-packages\pyrogram\client.py", line 685, in handle_updates
    diff = await self.invoke(
  File "C:\Users\aryas\AppData\Local\Programs\Python\Python310\lib\site-packages\pyrogram\methods\advanced\invoke.py", line 80, in invoke
    r = await self.session.invoke(
  File "C:\Users\aryas\AppData\Local\Programs\Python\Python310\lib\site-packages\pyrogram\session\session.py", line 433, in invoke
    return await self.send(query, timeout=timeout)
  File "C:\Users\aryas\AppData\Local\Programs\Python\Python310\lib\site-packages\pyrogram\session\session.py", line 377, in send
    RPCError.raise_it(result, type(data))
  File "C:\Users\aryas\AppData\Local\Programs\Python\Python310\lib\site-packages\pyrogram\errors\rpc_error.py", line 93, in raise_it
    raise getattr(
pyrogram.errors.exceptions.not_acceptable_406.AuthKeyDuplicated: Telegram says: [406 AUTH_KEY_DUPLICATED] (caused by "updates.GetChannelDifference") Pyrogram 2.3.62 thinks: The same authorization key (session file) was used in more than one place simultaneously. You must delete your session file and log in again with your phone number or bot token
[18-May-25 13:36:21 - ERROR] - asyncio - Task exception was never retrieved
future: <Task finished name='Task-1673' coro=<Client.handle_updates() done, defined at C:\Users\aryas\AppData\Local\Programs\Python\Python310\lib\site-packages\pyrogram\client.py:642> exception=AuthKeyDuplicated('Telegram says: [406 AUTH_KEY_DUPLICATED] (caused by "updates.GetChannelDifference") Pyrogram 2.3.62 thinks: The same authorization key (session file) was used in more than one place simultaneously. You must delete your session file and log in again with your phone number or bot token')>
Traceback (most recent call last):
  File "C:\Users\aryas\AppData\Local\Programs\Python\Python310\lib\site-packages\pyrogram\client.py", line 685, in handle_updates
    diff = await self.invoke(
  File "C:\Users\aryas\AppData\Local\Programs\Python\Python310\lib\site-packages\pyrogram\methods\advanced\invoke.py", line 80, in invoke
    r = await self.session.invoke(
  File "C:\Users\aryas\AppData\Local\Programs\Python\Python310\lib\site-packages\pyrogram\session\session.py", line 433, in invoke
    return await self.send(query, timeout=timeout)
  File "C:\Users\aryas\AppData\Local\Programs\Python\Python310\lib\site-packages\pyrogram\session\session.py", line 377, in send
    RPCError.raise_it(result, type(data))
  File "C:\Users\aryas\AppData\Local\Programs\Python\Python310\lib\site-packages\pyrogram\errors\rpc_error.py", line 93, in raise_it
    raise getattr(
pyrogram.errors.exceptions.not_acceptable_406.AuthKeyDuplicated: Telegram says: [406 AUTH_KEY_DUPLICATED] (caused by "updates.GetChannelDifference") Pyrogram 2.3.62 thinks: The same authorization key (session file) was used in more than one place simultaneously. You must delete your session file and log in again with your phone number or bot token
[18-May-25 13:36:26 - ERROR] - asyncio - Task exception was never retrieved
future: <Task finished name='Task-1707' coro=<Client.handle_updates() done, defined at C:\Users\aryas\AppData\Local\Programs\Python\Python310\lib\site-packages\pyrogram\client.py:642> exception=AuthKeyDuplicated('Telegram says: [406 AUTH_KEY_DUPLICATED] (caused by "updates.GetChannelDifference") Pyrogram 2.3.62 thinks: The same authorization key (session file) was used in more than one place simultaneously. You must delete your session file and log in again with your phone number or bot token')>
Traceback (most recent call last):
  File "C:\Users\aryas\AppData\Local\Programs\Python\Python310\lib\site-packages\pyrogram\client.py", line 685, in handle_updates
    diff = await self.invoke(
  File "C:\Users\aryas\AppData\Local\Programs\Python\Python310\lib\site-packages\pyrogram\methods\advanced\invoke.py", line 80, in invoke
    r = await self.session.invoke(
  File "C:\Users\aryas\AppData\Local\Programs\Python\Python310\lib\site-packages\pyrogram\session\session.py", line 433, in invoke
    return await self.send(query, timeout=timeout)
  File "C:\Users\aryas\AppData\Local\Programs\Python\Python310\lib\site-packages\pyrogram\session\session.py", line 377, in send
    RPCError.raise_it(result, type(data))
  File "C:\Users\aryas\AppData\Local\Programs\Python\Python310\lib\site-packages\pyrogram\errors\rpc_error.py", line 93, in raise_it
    raise getattr(
pyrogram.errors.exceptions.not_acceptable_406.AuthKeyDuplicated: Telegram says: [406 AUTH_KEY_DUPLICATED] (caused by "updates.GetChannelDifference") Pyrogram 2.3.62 thinks: The same authorization key (session file) was used in more than one place simultaneously. You must delete your session file and log in again with your phone number or bot token
[18-May-25 13:36:26 - ERROR] - asyncio - Task exception was never retrieved
future: <Task finished name='Task-1702' coro=<Client.handle_updates() done, defined at C:\Users\aryas\AppData\Local\Programs\Python\Python310\lib\site-packages\pyrogram\client.py:642> exception=AuthKeyDuplicated('Telegram says: [406 AUTH_KEY_DUPLICATED] (caused by "updates.GetChannelDifference") Pyrogram 2.3.62 thinks: The same authorization key (session file) was used in more than one place simultaneously. You must delete your session file and log in again with your phone number or bot token')>
Traceback (most recent call last):
  File "C:\Users\aryas\AppData\Local\Programs\Python\Python310\lib\site-packages\pyrogram\client.py", line 685, in handle_updates
    diff = await self.invoke(
  File "C:\Users\aryas\AppData\Local\Programs\Python\Python310\lib\site-packages\pyrogram\methods\advanced\invoke.py", line 80, in invoke
    r = await self.session.invoke(
  File "C:\Users\aryas\AppData\Local\Programs\Python\Python310\lib\site-packages\pyrogram\session\session.py", line 433, in invoke
    return await self.send(query, timeout=timeout)
  File "C:\Users\aryas\AppData\Local\Programs\Python\Python310\lib\site-packages\pyrogram\session\session.py", line 377, in send
    RPCError.raise_it(result, type(data))
  File "C:\Users\aryas\AppData\Local\Programs\Python\Python310\lib\site-packages\pyrogram\errors\rpc_error.py", line 93, in raise_it
    raise getattr(
pyrogram.errors.exceptions.not_acceptable_406.AuthKeyDuplicated: Telegram says: [406 AUTH_KEY_DUPLICATED] (caused by "updates.GetChannelDifference") Pyrogram 2.3.62 thinks: The same authorization key (session file) was used in more than one place simultaneously. You must delete your session file and log in again with your phone number or bot token
[18-May-25 13:36:26 - ERROR] - asyncio - Task exception was never retrieved
future: <Task finished name='Task-1706' coro=<Client.handle_updates() done, defined at C:\Users\aryas\AppData\Local\Programs\Python\Python310\lib\site-packages\pyrogram\client.py:642> exception=AuthKeyDuplicated('Telegram says: [406 AUTH_KEY_DUPLICATED] (caused by "updates.GetChannelDifference") Pyrogram 2.3.62 thinks: The same authorization key (session file) was used in more than one place simultaneously. You must delete your session file and log in again with your phone number or bot token')>
Traceback (most recent call last):
  File "C:\Users\aryas\AppData\Local\Programs\Python\Python310\lib\site-packages\pyrogram\client.py", line 685, in handle_updates
    diff = await self.invoke(
  File "C:\Users\aryas\AppData\Local\Programs\Python\Python310\lib\site-packages\pyrogram\methods\advanced\invoke.py", line 80, in invoke
    r = await self.session.invoke(
  File "C:\Users\aryas\AppData\Local\Programs\Python\Python310\lib\site-packages\pyrogram\session\session.py", line 433, in invoke
    return await self.send(query, timeout=timeout)
  File "C:\Users\aryas\AppData\Local\Programs\Python\Python310\lib\site-packages\pyrogram\session\session.py", line 377, in send
    RPCError.raise_it(result, type(data))
  File "C:\Users\aryas\AppData\Local\Programs\Python\Python310\lib\site-packages\pyrogram\errors\rpc_error.py", line 93, in raise_it
    raise getattr(
pyrogram.errors.exceptions.not_acceptable_406.AuthKeyDuplicated: Telegram says: [406 AUTH_KEY_DUPLICATED] (caused by "updates.GetChannelDifference") Pyrogram 2.3.62 thinks: The same authorization key (session file) was used in more than one place simultaneously. You must delete your session file and log in again with your phone number or bot token
[18-May-25 13:36:36 - ERROR] - asyncio - Task exception was never retrieved
future: <Task finished name='Task-1756' coro=<Client.handle_updates() done, defined at C:\Users\aryas\AppData\Local\Programs\Python\Python310\lib\site-packages\pyrogram\client.py:642> exception=AuthKeyDuplicated('Telegram says: [406 AUTH_KEY_DUPLICATED] (caused by "updates.GetChannelDifference") Pyrogram 2.3.62 thinks: The same authorization key (session file) was used in more than one place simultaneously. You must delete your session file and log in again with your phone number or bot token')>
Traceback (most recent call last):
  File "C:\Users\aryas\AppData\Local\Programs\Python\Python310\lib\site-packages\pyrogram\client.py", line 685, in handle_updates
    diff = await self.invoke(
  File "C:\Users\aryas\AppData\Local\Programs\Python\Python310\lib\site-packages\pyrogram\methods\advanced\invoke.py", line 80, in invoke
    r = await self.session.invoke(
  File "C:\Users\aryas\AppData\Local\Programs\Python\Python310\lib\site-packages\pyrogram\session\session.py", line 433, in invoke
    return await self.send(query, timeout=timeout)
  File "C:\Users\aryas\AppData\Local\Programs\Python\Python310\lib\site-packages\pyrogram\session\session.py", line 377, in send
    RPCError.raise_it(result, type(data))
  File "C:\Users\aryas\AppData\Local\Programs\Python\Python310\lib\site-packages\pyrogram\errors\rpc_error.py", line 93, in raise_it
    raise getattr(
pyrogram.errors.exceptions.not_acceptable_406.AuthKeyDuplicated: Telegram says: [406 AUTH_KEY_DUPLICATED] (caused by "updates.GetChannelDifference") Pyrogram 2.3.62 thinks: The same authorization key (session file) was used in more than one place simultaneously. You must delete your session file and log in again with your phone number or bot token
[18-May-25 13:36:36 - ERROR] - asyncio - Task exception was never retrieved
future: <Task finished name='Task-1753' coro=<Client.handle_updates() done, defined at C:\Users\aryas\AppData\Local\Programs\Python\Python310\lib\site-packages\pyrogram\client.py:642> exception=AuthKeyDuplicated('Telegram says: [406 AUTH_KEY_DUPLICATED] (caused by "updates.GetChannelDifference") Pyrogram 2.3.62 thinks: The same authorization key (session file) was used in more than one place simultaneously. You must delete your session file and log in again with your phone number or bot token')>
Traceback (most recent call last):
  File "C:\Users\aryas\AppData\Local\Programs\Python\Python310\lib\site-packages\pyrogram\client.py", line 685, in handle_updates
    diff = await self.invoke(
  File "C:\Users\aryas\AppData\Local\Programs\Python\Python310\lib\site-packages\pyrogram\methods\advanced\invoke.py", line 80, in invoke
    r = await self.session.invoke(
  File "C:\Users\aryas\AppData\Local\Programs\Python\Python310\lib\site-packages\pyrogram\session\session.py", line 433, in invoke
    return await self.send(query, timeout=timeout)
  File "C:\Users\aryas\AppData\Local\Programs\Python\Python310\lib\site-packages\pyrogram\session\session.py", line 377, in send
    RPCError.raise_it(result, type(data))
  File "C:\Users\aryas\AppData\Local\Programs\Python\Python310\lib\site-packages\pyrogram\errors\rpc_error.py", line 93, in raise_it
    raise getattr(
pyrogram.errors.exceptions.not_acceptable_406.AuthKeyDuplicated: Telegram says: [406 AUTH_KEY_DUPLICATED] (caused by "updates.GetChannelDifference") Pyrogram 2.3.62 thinks: The same authorization key (session file) was used in more than one place simultaneously. You must delete your session file and log in again with your phone number or bot token
[18-May-25 13:36:36 - ERROR] - asyncio - Task exception was never retrieved
future: <Task finished name='Task-1752' coro=<Client.handle_updates() done, defined at C:\Users\aryas\AppData\Local\Programs\Python\Python310\lib\site-packages\pyrogram\client.py:642> exception=AuthKeyDuplicated('Telegram says: [406 AUTH_KEY_DUPLICATED] (caused by "updates.GetChannelDifference") Pyrogram 2.3.62 thinks: The same authorization key (session file) was used in more than one place simultaneously. You must delete your session file and log in again with your phone number or bot token')>
Traceback (most recent call last):
  File "C:\Users\aryas\AppData\Local\Programs\Python\Python310\lib\site-packages\pyrogram\client.py", line 685, in handle_updates
    diff = await self.invoke(
  File "C:\Users\aryas\AppData\Local\Programs\Python\Python310\lib\site-packages\pyrogram\methods\advanced\invoke.py", line 80, in invoke
    r = await self.session.invoke(
  File "C:\Users\aryas\AppData\Local\Programs\Python\Python310\lib\site-packages\pyrogram\session\session.py", line 433, in invoke
    return await self.send(query, timeout=timeout)
  File "C:\Users\aryas\AppData\Local\Programs\Python\Python310\lib\site-packages\pyrogram\session\session.py", line 377, in send
    RPCError.raise_it(result, type(data))
  File "C:\Users\aryas\AppData\Local\Programs\Python\Python310\lib\site-packages\pyrogram\errors\rpc_error.py", line 93, in raise_it
    raise getattr(
pyrogram.errors.exceptions.not_acceptable_406.AuthKeyDuplicated: Telegram says: [406 AUTH_KEY_DUPLICATED] (caused by "updates.GetChannelDifference") Pyrogram 2.3.62 thinks: The same authorization key (session file) was used in more than one place simultaneously. You must delete your session file and log in again with your phone number or bot token
[18-May-25 13:36:41 - ERROR] - asyncio - Task exception was never retrieved
future: <Task finished name='Task-1786' coro=<Client.handle_updates() done, defined at C:\Users\aryas\AppData\Local\Programs\Python\Python310\lib\site-packages\pyrogram\client.py:642> exception=AuthKeyDuplicated('Telegram says: [406 AUTH_KEY_DUPLICATED] (caused by "updates.GetChannelDifference") Pyrogram 2.3.62 thinks: The same authorization key (session file) was used in more than one place simultaneously. You must delete your session file and log in again with your phone number or bot token')>
Traceback (most recent call last):
  File "C:\Users\aryas\AppData\Local\Programs\Python\Python310\lib\site-packages\pyrogram\client.py", line 685, in handle_updates
    diff = await self.invoke(
  File "C:\Users\aryas\AppData\Local\Programs\Python\Python310\lib\site-packages\pyrogram\methods\advanced\invoke.py", line 80, in invoke
    r = await self.session.invoke(
  File "C:\Users\aryas\AppData\Local\Programs\Python\Python310\lib\site-packages\pyrogram\session\session.py", line 433, in invoke
    return await self.send(query, timeout=timeout)
  File "C:\Users\aryas\AppData\Local\Programs\Python\Python310\lib\site-packages\pyrogram\session\session.py", line 377, in send
    RPCError.raise_it(result, type(data))
  File "C:\Users\aryas\AppData\Local\Programs\Python\Python310\lib\site-packages\pyrogram\errors\rpc_error.py", line 93, in raise_it
    raise getattr(
pyrogram.errors.exceptions.not_acceptable_406.AuthKeyDuplicated: Telegram says: [406 AUTH_KEY_DUPLICATED] (caused by "updates.GetChannelDifference") Pyrogram 2.3.62 thinks: The same authorization key (session file) was used in more than one place simultaneously. You must delete your session file and log in again with your phone number or bot token
[18-May-25 13:36:51 - ERROR] - asyncio - Task exception was never retrieved
future: <Task finished name='Task-1817' coro=<Client.handle_updates() done, defined at C:\Users\aryas\AppData\Local\Programs\Python\Python310\lib\site-packages\pyrogram\client.py:642> exception=AuthKeyDuplicated('Telegram says: [406 AUTH_KEY_DUPLICATED] (caused by "updates.GetChannelDifference") Pyrogram 2.3.62 thinks: The same authorization key (session file) was used in more than one place simultaneously. You must delete your session file and log in again with your phone number or bot token')>
Traceback (most recent call last):
  File "C:\Users\aryas\AppData\Local\Programs\Python\Python310\lib\site-packages\pyrogram\client.py", line 685, in handle_updates
    diff = await self.invoke(
  File "C:\Users\aryas\AppData\Local\Programs\Python\Python310\lib\site-packages\pyrogram\methods\advanced\invoke.py", line 80, in invoke
    r = await self.session.invoke(
  File "C:\Users\aryas\AppData\Local\Programs\Python\Python310\lib\site-packages\pyrogram\session\session.py", line 433, in invoke
    return await self.send(query, timeout=timeout)
  File "C:\Users\aryas\AppData\Local\Programs\Python\Python310\lib\site-packages\pyrogram\session\session.py", line 377, in send
    RPCError.raise_it(result, type(data))
  File "C:\Users\aryas\AppData\Local\Programs\Python\Python310\lib\site-packages\pyrogram\errors\rpc_error.py", line 93, in raise_it
    raise getattr(
pyrogram.errors.exceptions.not_acceptable_406.AuthKeyDuplicated: Telegram says: [406 AUTH_KEY_DUPLICATED] (caused by "updates.GetChannelDifference") Pyrogram 2.3.62 thinks: The same authorization key (session file) was used in more than one place simultaneously. You must delete your session file and log in again with your phone number or bot token
[18-May-25 13:36:54 - INFO] - root - Stop signal received (SIGINT). Exiting...
[18-May-25 13:36:54 - INFO] - Reex.core.userbot - Stopping Assistants...
[18-May-25 13:36:54 - INFO] - AryaaMusic - Stopping AryaaMusic Bot...
[18-May-25 13:39:32 - INFO] - Reex.core.mongo - Connecting to your Mongo Database...
[18-May-25 13:39:32 - INFO] - Reex.core.mongo - Connected to your Mongo Database.
[18-May-25 13:39:32 - INFO] - Reex.core.dir - Directories Updated.
[18-May-25 13:39:32 - INFO] - Reex.core.git - Git Client Found [VPS DEPLOYER]
[18-May-25 13:39:32 - INFO] - Reex.misc - Local Database Initialized.
[18-May-25 13:39:32 - INFO] - Reex.core.bot - Starting Bot...
[18-May-25 13:39:35 - INFO] - Reex.misc - Sudoers Loaded.
